<?xml version="1.0"?>
<robot name="differential_drive_robot" xmlns:xacro="http://www.ros.org/wiki/xacro">

  <xacro:property name="body_link_x_dim" value="1"/>
  <xacro:property name="body_link_y_dim" value="0.6"/>
  <xacro:property name="body_link_z_dim" value="0.3"/>

  <xacro:property name="wheel_link_radius" value="0.15"/>
  <xacro:property name="wheel_link_length" value="0.1"/>
  <xacro:property name="wheel_link_z_location" value="-0.1"/>

  <xacro:property name="caster_link_radius" value="0.15"/>
  <xacro:property name="caster_link_z_location" value="-0.1"/>
  
  <xacro:property name="lidar_radius" value="0.08"/>
  <xacro:property name="lidar_length" value="0.06"/>

  <xacro:property name="camera_length" value="0.15"/>
  

  <xacro:property name="body_density" value="2710.0"/>
  <xacro:property name="wheel_density" value="2710.0"/>
  <xacro:property name="caster_density" value="2710.0"/>

  <xacro:property name="pi_const" value="3.14159265"/>

  <xacro:property name="body_mass" value="${body_density * body_link_x_dim * body_link_y_dim * body_link_z_dim}"/>
  <xacro:property name="wheel_mass" value="${wheel_density * pi_const * wheel_link_radius * wheel_link_radius * wheel_link_length}"/>
  <xacro:property name="caster_mass" value="${caster_density * (4.0/3.0) * pi_const * caster_link_radius * caster_link_radius * caster_link_radius}"/>

  <xacro:property name="Iz_wheel" value="${0.5*wheel_mass*wheel_link_radius*wheel_link_radius}" />
  <xacro:property name="I_wheel" value="${(1.0/12.0)*wheel_mass*(3.0*wheel_link_radius*wheel_link_radius+wheel_link_length*wheel_link_length)}" />
  <xacro:property name="I_caster" value="${(2.0/5.0)*caster_mass*caster_link_radius*caster_link_radius}" />

  <xacro:macro name="inertia_wheel">
    <inertial>
      <origin rpy="0 0 0" xyz="0 0 0"/>
      <mass value="${wheel_mass}"/>
      <inertia ixx="${I_wheel}" ixy="0.0" ixz="0.0" iyy="${I_wheel}" iyz="0" izz="${Iz_wheel}" />
    </inertial>
  </xacro:macro>

  <xacro:macro name="inertia_caster">
    <inertial>
      <origin rpy="0 0 0" xyz="0 0 0"/>
      <mass value="${caster_mass}"/>
      <inertia ixx="${I_caster}" ixy="0.0" ixz="0.0" iyy="${I_caster}" iyz="0.0" izz="${I_caster}" />
    </inertial>
  </xacro:macro>

  <link name="base_footprint"/>

  <joint name="base_footprint_joint" type="fixed">
    <parent link="base_footprint"/>
    <child link="base_link"/>
    <origin xyz="0 0 0" rpy="0 0 0"/>
  </joint>

  <link name="base_link"></link>

  <joint name="base_joint" type="fixed">
    <parent link="base_link"/>
    <child link="body_link"/>
    <origin xyz="0 0 0" rpy="0 0 0"/>
  </joint>

  <link name="body_link">
    <visual>
      <geometry>
        <box size="${body_link_x_dim} ${body_link_y_dim} ${body_link_z_dim}" />
      </geometry>
      <origin rpy="0 0 0" xyz="0 0 0"/>
      <material name="blue">
        <color rgba="0.0 0.3 0.8 1.0"/>
      </material>
    </visual>
    <collision>
      <geometry>
        <box size="${body_link_x_dim} ${body_link_y_dim} ${body_link_z_dim}" />
      </geometry>
      <origin rpy="0 0 0" xyz="0 0 0"/>
    </collision>
    <inertial>
      <origin rpy="0 0 0" xyz="0 0 0"/>
      <mass value="${body_mass}"/>
      <inertia
        ixx="${(1/12)*body_mass*(body_link_y_dim*body_link_y_dim+body_link_z_dim*body_link_z_dim)}" ixy="0" ixz="0"
        iyy="${(1/12)*body_mass*(body_link_x_dim*body_link_x_dim+body_link_z_dim*body_link_z_dim)}" iyz="0"
        izz="${(1/12)*body_mass*(body_link_y_dim*body_link_y_dim+body_link_x_dim*body_link_x_dim)}" />
    </inertial>
  </link>

  <joint name="wheel1_joint" type="continuous">
    <parent link="body_link"/>
    <child link="wheel1_link"/>
    <origin xyz="${-2*wheel_link_radius} ${-body_link_y_dim/2-wheel_link_length/2} ${wheel_link_z_location}" rpy="0 0 0"/>
    <axis xyz="0 1 0"/>
    <limit effort="1000" velocity="1000"/>
    <dynamics damping="1.0" friction="1.0"/>
  </joint>

  <link name="wheel1_link">
    <visual>
      <origin rpy="1.570795 0 0" xyz="0 0 0"/>
      <geometry>
        <cylinder length="${wheel_link_length}" radius="${wheel_link_radius}"/>
      </geometry>
      <material name="black">
        <color rgba="0.1 0.1 0.1 1.0"/>
      </material>
    </visual>
    <collision>
      <origin rpy="1.570795 0 0" xyz="0 0 0"/>
      <geometry>
        <cylinder length="${wheel_link_length}" radius="${wheel_link_radius}"/>
      </geometry>
    </collision>
    <xacro:inertia_wheel />
  </link>

  <joint name="wheel2_joint" type="continuous">
    <parent link="body_link"/>
    <child link="wheel2_link"/>
    <origin xyz="${-2*wheel_link_radius} ${body_link_y_dim/2+wheel_link_length/2} ${wheel_link_z_location}" rpy="0 0 0"/>
    <axis xyz="0 1 0"/>
    <limit effort="1000" velocity="1000"/>
    <dynamics damping="1.0" friction="1.0"/>
  </joint>

  <link name="wheel2_link">
    <visual>
      <origin rpy="1.570795 0 0" xyz="0 0 0"/>
      <geometry>
        <cylinder length="${wheel_link_length}" radius="${wheel_link_radius}"/>
      </geometry>
      <material name="black">
        <color rgba="0.1 0.1 0.1 1.0"/>
      </material>
    </visual>
    <collision>
      <origin rpy="1.570795 0 0" xyz="0 0 0"/>
      <geometry>
        <cylinder length="${wheel_link_length}" radius="${wheel_link_radius}"/>
      </geometry>
    </collision>
    <xacro:inertia_wheel />
  </link>

  <joint name="caster_joint" type="fixed">
    <parent link="body_link"/>
    <child link="caster_link"/>
    <origin xyz="${2*caster_link_radius} 0 ${caster_link_z_location}" rpy="0 0 0"/>
  </joint>

  <link name="caster_link">
    <visual>
      <origin rpy="0 0 0" xyz="0 0 0"/>
      <geometry>
        <sphere radius="${caster_link_radius}" />
      </geometry>
      <material name="grey">
        <color rgba="0.5 0.5 0.5 1.0"/>
      </material>
    </visual>
    <collision>
      <origin rpy="0 0 0" xyz="0 0 0"/>
      <geometry>
        <sphere radius="${caster_link_radius}" />
      </geometry>
    </collision>
    <xacro:inertia_caster />
  </link>

  <joint name="camera_joint" type="fixed">
    <parent link="body_link"/>
    <child link="camera_link"/>
    <origin xyz="${camera_length/3.5 + body_link_x_dim/2 } 0 0" rpy="0 0 0"/>
  </joint>

  <link name="camera_link">
    <visual>
      <geometry>
        <box size="${camera_length/1.75} ${camera_length} ${camera_length}"/>
      </geometry>
      <material name="black">
        <color rgba="0.1 0.1 0.1 1.0"/>
      </material>
    </visual>
    <collision>
      <geometry>
        <box size="${camera_length/1.75} ${camera_length} ${camera_length}"/>
      </geometry>
    </collision>
    <inertial>
      <mass value="0.2"/>
      <origin xyz="0 0 0" rpy="0 0 0"/>
      <inertia ixx="0.0001" ixy="0" ixz="0" iyy="0.0001" iyz="0" izz="0.0001"/>
    </inertial>
  </link>

  <joint name="camera_optical_joint" type="fixed">
    <parent link="camera_link"/>
    <child link="camera_optical_link"/>
    <origin xyz="0 0 0" rpy="${-pi_const/2} 0 ${-pi_const/2}"/>
  </joint>

  <link name="camera_optical_link"></link>


  <joint name="lidar_joint" type="fixed">
    <parent link="body_link"/>
    <child link="lidar_link"/>
    <origin xyz="0.3 0 ${body_link_z_dim/2 + lidar_length/2}" rpy="0 0 0"/>
  </joint>

  <link name="lidar_link">
    <visual>
      <geometry>
        <cylinder radius="${lidar_radius}" length="${lidar_length}"/>
      </geometry>
      <material name="black">
        <color rgba="0.1 0.1 0.1 1.0"/>
      </material>
    </visual>
    <collision>
      <geometry>
        <cylinder radius="${lidar_radius}" length="${lidar_length}"/>
      </geometry>
    </collision>
    <inertial>
      <mass value="0.5"/>
      <origin xyz="0 0 0" rpy="0 0 0"/>
      <inertia ixx="0.0001" ixy="0" ixz="0" iyy="0.0001" iyz="0" izz="0.0001"/>
    </inertial>
  </link>

  <gazebo reference="body_link">
    <visual>
      <material>
        <ambient>0.0 0.3 0.8 1.0</ambient>
        <diffuse>0.0 0.3 0.8 1.0</diffuse>
      </material>
    </visual>
    <mu1>0.2</mu1>
    <mu2>0.2</mu2>
  </gazebo>

  <gazebo reference="wheel1_link">
    <visual>
      <material>
        <ambient>0.1 0.1 0.1 1.0</ambient>
        <diffuse>0.1 0.1 0.1 1.0</diffuse>
      </material>
    </visual>
    <mu1>1.0</mu1>
    <mu2>1.0</mu2>
  </gazebo>

  <gazebo reference="wheel2_link">
    <visual>
      <material>
        <ambient>0.1 0.1 0.1 1.0</ambient>
        <diffuse>0.1 0.1 0.1 1.0</diffuse>
      </material>
    </visual>
    <mu1>1.0</mu1>
    <mu2>1.0</mu2>
  </gazebo>

  <gazebo reference="caster_link">
    <visual>
      <material>
        <ambient>0.5 0.5 0.5 1.0</ambient>
        <diffuse>0.5 0.5 0.5 1.0</diffuse>
      </material>
    </visual>
    <mu1>0.001</mu1>
    <mu2>0.001</mu2>
  </gazebo>

  <gazebo reference="lidar_link">
    <visual>
      <material>
        <ambient>0.1 0.1 0.1 1.0</ambient>
        <diffuse>0.1 0.1 0.1 1.0</diffuse>
      </material>
    </visual>
    <sensor name="lidar_sensor" type="gpu_lidar">
      <topic>/scan</topic>
      <ignition_frame_id>lidar_link</ignition_frame_id> 
      <update_rate>10</update_rate>
      <ray>
        <scan>
          <horizontal>
            <samples>360</samples>
            <resolution>1</resolution>
            <min_angle>-3.14159</min_angle>
            <max_angle>3.14159</max_angle>
          </horizontal>
        </scan>
        <range>
          <min>0.15</min>
          <max>10.0</max>
          <resolution>0.01</resolution>
        </range>
      </ray>
      <always_on>1</always_on>
      <visualize>true</visualize>
    </sensor>
  </gazebo>

  <gazebo reference="camera_link">
    <sensor name="camera" type="camera">
      <pose> 0 0 0 0 0 0 </pose>
      <visualize>true</visualize>
      <update_rate>30</update_rate>
      <camera>
        <horizontal_fov>1.05</horizontal_fov>
        <image>
          <format>R8G8B8</format>
          <width>640</width>
          <height>480</height>
        </image>
        <clip>
          <near>0.05</near>
          <far>4.0</far>
        </clip>
      </camera>
      <ignition_frame_id>camera_optical_link</ignition_frame_id>
      <topic>camera/image_raw</topic>
    </sensor>
  </gazebo>

  <gazebo>
    <plugin
      filename="ignition-gazebo-diff-drive-system"
      name="ignition::gazebo::systems::DiffDrive">
      <left_joint>wheel2_joint</left_joint>
      <right_joint>wheel1_joint</right_joint>
      <wheel_separation>0.7</wheel_separation>
      <wheel_radius>0.15</wheel_radius>
      <max_wheel_torque>200</max_wheel_torque>
      <max_wheel_acceleration>10.0</max_wheel_acceleration>
      <topic>cmd_vel</topic>
      <odom_topic>odom</odom_topic>
      <tf_topic>tf</tf_topic>
      <frame_id>odom</frame_id>
      <child_frame_id>base_footprint</child_frame_id>
    </plugin>

    <plugin
      filename="ignition-gazebo-sensors-system"
      name="ignition::gazebo::systems::Sensors">
      <render_engine>ogre2</render_engine>
    </plugin>

    <plugin
      filename="ignition-gazebo-joint-state-publisher-system"
      name="ignition::gazebo::systems::JointStatePublisher">
    </plugin>
  </gazebo>

</robot>